[28/Nov/2017 05:32:47] ERROR [django.request:135] Internal Server Error: /api/v1/tiles/
Traceback (most recent call last):
  File "/opt/conda/lib/python3.6/site-packages/django/core/handlers/exception.py", line 41, in inner
    response = get_response(request)
  File "/opt/conda/lib/python3.6/site-packages/django/core/handlers/base.py", line 187, in _get_response
    response = self.process_exception_by_middleware(e, request)
  File "/opt/conda/lib/python3.6/site-packages/django/core/handlers/base.py", line 185, in _get_response
    response = wrapped_callback(request, *callback_args, **callback_kwargs)
  File "/opt/conda/lib/python3.6/site-packages/django/views/decorators/csrf.py", line 58, in wrapped_view
    return view_func(*args, **kwargs)
  File "/opt/conda/lib/python3.6/site-packages/django/views/generic/base.py", line 68, in view
    return self.dispatch(request, *args, **kwargs)
  File "/opt/conda/lib/python3.6/site-packages/rest_framework/views.py", line 489, in dispatch
    response = self.handle_exception(exc)
  File "/opt/conda/lib/python3.6/site-packages/rest_framework/views.py", line 449, in handle_exception
    self.raise_uncaught_exception(exc)
  File "/opt/conda/lib/python3.6/site-packages/rest_framework/views.py", line 486, in dispatch
    response = handler(request, *args, **kwargs)
  File "/opt/conda/lib/python3.6/site-packages/rest_framework/decorators.py", line 52, in handler
    return func(*args, **kwargs)
  File "./tilesets/views.py", line 553, in tiles
    result_dict = dict([i for i in res if i is not None])
  File "./tilesets/views.py", line 553, in <listcomp>
    result_dict = dict([i for i in res if i is not None])
  File "./tilesets/views.py", line 550, in <lambda>
    res = map(lambda x: generate_tile(x, request), tileids_to_fetch)
  File "./tilesets/views.py", line 154, in generate_tile
    tileset = tm.Tileset.objects.get(uuid=tileset_uuid)
  File "/opt/conda/lib/python3.6/site-packages/django/db/models/manager.py", line 85, in manager_method
    return getattr(self.get_queryset(), name)(*args, **kwargs)
  File "/opt/conda/lib/python3.6/site-packages/django/db/models/query.py", line 380, in get
    self.model._meta.object_name
tilesets.models.DoesNotExist: Tileset matching query does not exist.
[28/Nov/2017 06:10:04] WARNING [django.security.SuspiciousSession:117] Session data corrupted
